Workbook
Name ABC: Catalogo!$B$2:$B$4
Name C_ADSCRIPCION: Aux!$D$2:$D$69
Name C_AUTORIZO: Aux!$B$4:$B$18
Name C_CENTROT: Aux!$F$2:$F$1175
Name C_EMPLEADO: Aux!$C$2:$C$702
Name C_ENTIDADF: Aux!$A$2:$A$33
Name C_OFICINA: Aux!$E$2:$E$1124
Name ESTADOS: Aux!$A$2:$A$29
Name LICENCIA: Catalogo!$B$13:$B$13
Name Perfiles_de_acceso_a_internet: Catalogo!$B$5:$B$12
Name Servicios: Catalogo!$C$2:$C$4
Name TCentroDeTrabajo: Domicilios!$I$2:$I$1360
Name TDOMICILIOS: Domicilios!$A$2:$L$1360
Name Unidad_Administrativa: Aux!$D$2:$D$69

Sheet Formato
K1: SUBDIRECCIÓN DE TECNOLOGÍA DE LA INFORMACIÓN SUBCOORDINACIÓN DE GOBERNANZA TECNOLÓGICA | Y1: Hoja: | AA1: 1 de 1
Y3: Código: | AA3: NA
K4: JEFATURA DE SERVICIOS DE MESA CENTRAL DE SERVICIOS | Y4: Versión: | AA4: 8.0
K5: DEPARTAMENTO DE SERVICIOS DE INTERNET
K6: CÉDULA DE CONTROL DE USUARIOS DE SERVICIOS DE COMUNICACIÓN | Y6: Fecha: | AA6: 45827
K7: SERVICIOS DE INTERNET
B8: DATOS DEL USUARIO | D8: FECHA: | H8: 46231
D9: EN ESTE APARTADO FAVOR DE COLOCAR LA INFORMACIÓN QUE CUMPLA CON LOS SIGUIENTES CRITERIOS: MAYÚSCULAS Y MINÚSCULAS SIN ACENTOS SIN CARACTERES ESPECIALES CAMBIAR LA LETRA "Ñ" POR "N"
D10: NOMBRE(S): | H10: Zaira | R10: APELLIDOS: | T10: Colorado Rodríguez
D11: No. EMPLEADO: | H11: 440538 | K11: PUESTO: | N11: Subjefa de Farmacia | AA11: RED: | AB11: 31082
D12: ENTIDAD FEDERATIVA: | H12: Veracruz | M12: CENTRO DE TRABAJO: | S12: CH Xalapa
D13: DOMICILIO: | H13: =IFERROR(VLOOKUP(CONCATENATE(H12,"-",S12),TDOMICILIOS,10,FALSE)," ") -> Fraternidad Esq. Jose Hernandez Col. Obrero Campesina | T13: LOCALIDAD: | X13: =IFERROR(VLOOKUP(CONCATENATE(H12,"-",S12),TDOMICILIOS,11,FALSE)," ") -> Xalapa
D14: CODIGO POSTAL: | H14: =IFERROR(VLOOKUP(CONCATENATE(H12,"-",S12),TDOMICILIOS,12,FALSE)," ") -> 91020 | K14: TIPO DE UNIDAD: | O14: =IFERROR(VLOOKUP(CONCATENATE(H12,"-",S12),TDOMICILIOS,7,FALSE)," ") -> Unidad Medica | T14: CLUE: | V14: =IFERROR(VLOOKUP(CONCATENATE(H12,"-",S12),TDOMICILIOS,3,FALSE),"") -> VZIST000120
D15: OFICINA: | H15: Farmacia | S15: CLAVE PRESUPUESTAL : | Y15: =IFERROR(VLOOKUP(CONCATENATE(H12,"-",S12),TDOMICILIOS,4,FALSE)," ") -> 030-204-00
D16: AREA DE ADSCRIPCIÓN: | H16: Representacion Estatal Veracruz | S16: DIRECCION IP: | Y16: 192.160.197.228
S17: HOSTNAME: | Y17: 03020400-23DN05
B18: DATOS DE LA CONFIGURACIÓN
D19: TIPO DE SOLICITUD: | H19: ALTA | R19: TIPO DE CONTRATACION: | X19: Estructura
D20: SERVICIO: | H20: ABC
D21: CATEGORIA: | H21: AD-EX USUARIO Y CUENTA DE CORREO
B22: TIPO DE SOLICITUD O SERVICIO
D23: =IFERROR(VLOOKUP((H19&" - "&H20&" - "&H21),Comentarios!A:D,4,0),"") -> Si el tipo de solicitud es una alta de usuario y/o cuenta de correo electrónico de nuevo ingreso, previamente debe levantar el ticket de la baja del servidor publico que deja el cargo e indicar el usuario y No. de ticket.
B28: DESCRIPCIÓN Y JUSTIFICACIÓN | D28: =IFERROR(VLOOKUP((H19&" - "&H20&" - "&H21),Comentarios!A:E,5,0),"") -> En caso de solicitar un alta de usuario y/o de cuenta de correo electrónico para personal operativo, favor de indicar el detalle de las funciones del usuario que lo justifique.
D30: Se solicita alta de usuario de correo electrónico y equipo de computo institucional para realizar solicitudes de los insumos en el sistema SIAM asi como para la recepción y control de las altas y bajas de los medicamentos e insumos hospitalarios y para facilitar las funciones que le fueron asignadas, asi como para el manejo de los equipos del área de farmacia.
B33: Vo. Bo.
D34: NOMBRE DE QUIEN AUTORIZA: | K34: Brenda Berenice Hernández Herrera
D35: CARGO: | K35: Subdirectora
B37: FIRMAS
D38: =IFERROR(VLOOKUP((H19&" - "&H20&" - "&H21),Comentarios!A:F,6,0),"") -> USUARIO | K38: =IFERROR(VLOOKUP((H19&" - "&H20&" - "&H21),Comentarios!A:G,7,0),"") -> ENLACE INFORMATICO | T38: =IFERROR(VLOOKUP((H19&" - "&H20&" - "&H21),Comentarios!A:H,8,0),"") -> JEFE DE SERVICIOS O SUPERIOR
D39: =CONCATENATE(H10," ",T10) -> Zaira Colorado Rodríguez | K39: Hugo Landero López | T39: Brenda Berenice Hernández Herrera
B45: =IFERROR(VLOOKUP((H19&" - "&H20&" - "&H21),Comentarios!A:I,9,0),"") -> El presente documento es una responsiva mediante la cual el usuario acepta las Políticas de uso del servicio solicitado, publicadas en la Intranet del Instituto en el siguiente link: https://www.issste.gob.mx/intranet/direccionnormativa/adminitracionyfinanzas/sudireccion/masinfo/acuerdotic.html

Sheet Formato (2)
K1: SUBDIRECCIÓN DE TECNOLOGÍA DE LA INFORMACIÓN SUBCOORDINACIÓN DE GOBERNANZA TECNOLÓGICA | Y1: Hoja: | AA1: 1 de 1
Y3: Código: | AA3: NA
K4: JEFATURA DE SERVICIOS DE MESA CENTRAL DE SERVICIOS | Y4: Versión: | AA4: 8.0
K5: DEPARTAMENTO DE SERVICIOS DE INTERNET
K6: CÉDULA DE CONTROL DE USUARIOS DE SERVICIOS DE COMUNICACIÓN | Y6: Fecha: | AA6: 45827
K7: SERVICIOS DE INTERNET
B8: DATOS DEL USUARIO | D8: FECHA: | H8: 46231
D9: EN ESTE APARTADO FAVOR DE COLOCAR LA INFORMACIÓN QUE CUMPLA CON LOS SIGUIENTES CRITERIOS: MAYÚSCULAS Y MINÚSCULAS SIN ACENTOS SIN CARACTERES ESPECIALES CAMBIAR LA LETRA "Ñ" POR "N"
D10: NOMBRE(S): | R10: APELLIDOS:
D11: No. EMPLEADO: | K11: PUESTO: | N11: Subdirector de CH A | AA11: RED:
D12: ENTIDAD FEDERATIVA: | H12: Veracruz | M12: CENTRO DE TRABAJO: | S12: CH Xalapa
D13: DOMICILIO: | H13: =IFERROR(VLOOKUP(CONCATENATE(H12,"-",S12),TDOMICILIOS,10,FALSE)," ") -> Fraternidad Esq. Jose Hernandez Col. Obrero Campesina | T13: LOCALIDAD: | X13: =IFERROR(VLOOKUP(CONCATENATE(H12,"-",S12),TDOMICILIOS,11,FALSE)," ") -> Xalapa
D14: CODIGO POSTAL: | H14: =IFERROR(VLOOKUP(CONCATENATE(H12,"-",S12),TDOMICILIOS,12,FALSE)," ") -> 91020 | K14: TIPO DE UNIDAD: | O14: =IFERROR(VLOOKUP(CONCATENATE(H12,"-",S12),TDOMICILIOS,7,FALSE)," ") -> Unidad Medica | T14: CLUE: | V14: =IFERROR(VLOOKUP(CONCATENATE(H12,"-",S12),TDOMICILIOS,3,FALSE),"") -> VZIST000120
D15: OFICINA: | H15: Subdireccion Medica CH | S15: CLAVE PRESUPUESTAL : | Y15: =IFERROR(VLOOKUP(CONCATENATE(H12,"-",S12),TDOMICILIOS,4,FALSE)," ") -> 030-204-00
D16: AREA DE ADSCRIPCIÓN: | H16: Representacion Estatal Veracruz | S16: DIRECCION IP:
S17: HOSTNAME:
B18: DATOS DE LA CONFIGURACIÓN
D19: TIPO DE SOLICITUD: | H19: ALTA | R19: TIPO DE CONTRATACION: | X19: Estructura
D20: SERVICIO: | H20: ABC
D21: CATEGORIA: | H21: AD-EX USUARIO Y CUENTA DE CORREO
B22: TIPO DE SOLICITUD O SERVICIO
D23: =IFERROR(VLOOKUP((H19&" - "&H20&" - "&H21),Comentarios!A:D,4,0),"") -> Si el tipo de solicitud es una alta de usuario y/o cuenta de correo electrónico de nuevo ingreso, previamente debe levantar el ticket de la baja del servidor publico que deja el cargo e indicar el usuario y No. de ticket.
B28: DESCRIPCIÓN Y JUSTIFICACIÓN | D28: =IFERROR(VLOOKUP((H19&" - "&H20&" - "&H21),Comentarios!A:E,5,0),"") -> En caso de solicitar un alta de usuario y/o de cuenta de correo electrónico para personal operativo, favor de indicar el detalle de las funciones del usuario que lo justifique.
D30: Se solicita alta de usuario de correo electrónico y equipo de computo institucional para realizar actividades como Subdirector Médico en la Clinica Hospital ISSSTE Xalapa.
B33: Vo. Bo.
D34: NOMBRE DE QUIEN AUTORIZA: | K34: Dr. Samuel Ferrer Palacios
D35: CARGO: | K35: Director
B37: FIRMAS
D38: =IFERROR(VLOOKUP((H19&" - "&H20&" - "&H21),Comentarios!A:F,6,0),"") -> USUARIO | K38: =IFERROR(VLOOKUP((H19&" - "&H20&" - "&H21),Comentarios!A:G,7,0),"") -> ENLACE INFORMATICO | T38: =IFERROR(VLOOKUP((H19&" - "&H20&" - "&H21),Comentarios!A:H,8,0),"") -> JEFE DE SERVICIOS O SUPERIOR
D39: =CONCATENATE(H10," ",T10) | K39: Hugo Landero López | T39: Dr. Samuel Ferrer Palacios
B45: =IFERROR(VLOOKUP((H19&" - "&H20&" - "&H21),Comentarios!A:I,9,0),"") -> El presente documento es una responsiva mediante la cual el usuario acepta las Políticas de uso del servicio solicitado, publicadas en la Intranet del Instituto en el siguiente link: https://www.issste.gob.mx/intranet/direccionnormativa/adminitracionyfinanzas/sudireccion/masinfo/acuerdotic.html

Sheet Domicilios
A1: LLAVE | B1: ID | C1: CLUE | D1: CLAVE PRESUPUESTAL | E1: cve guion bajo | F1: TIPOLOGIA | G1: TIPO DE UNIDAD | H1: CIUDAD | I1: NOMBRE DE LA UNIDAD | J1: DOMICILIO | K1: LOCALIDAD | L1: C.P.
A2: Aguascalientes-Almacen Estatal Aguascalientes | B2: 2059 | C2: No aplica | D2: 001-142-00 | E2: 001_142_00_Almacen_Estatal_Aguascalientes | F2: AE | G2: Unidad Administrativa | H2: Aguascalientes | I2: Almacen Estatal Aguascalientes | J2: Heroe de Nacozari Norte No. 2402 Col. Las Hadas | K2: Aguascalientes | L2: 20140
A3: Baja California-Almacen Estatal Baja California | B3: 2325 | C3: No aplica | D3: 002-142-00 | E3: 002_142_00_Almacen_Estatal_Baja_California | F3: AE | G3: Unidad Administrativa | H3: Baja California | I3: Almacen Estatal Baja California | J3: Centro Comercial Plaza Mandarin Local 26 D Col. Fracc. Las Palmas | K3: Mexicali | L3: 21110
A4: Baja California Sur-Almacen Estatal Baja California Sur | B4: 2819 | C4: No aplica | D4: 003-142-00 | E4: 003_142_00_Almacen_Estatal_Baja_California_Sur | F4: AE | G4: Unidad Administrativa | H4: Baja California Sur | I4: Almacen Estatal Baja California Sur | J4: Cavildos SN entre Campo y Degollado Col. Francisco Villa | K4: La Paz | L4: 23040
A5: Campeche-Almacen Estatal Campeche | B5: 2332 | C5: No aplica | D5: 004-142-00 | E5: 004_142_00_Almacen_Estatal_Campeche | F5: AE | G5: Unidad Administrativa | H5: Campeche | I5: Almacen Estatal Campeche | J5: Ciriaco Vazquez No. 89A Col. Centro | K5: Campeche | L5: 24000
A6: Chiapas-Almacen Estatal Chiapas | B6: 2928 | C6: No aplica | D6: 007-142-00 | E6: 007_142_00_Almacen_Estatal_Chiapas | F6: AE | G6: Unidad Administrativa | H6: Chiapas | I6: Almacen Estatal Chiapas | J6: Anillo Circunvalacion No. 1515 Col. Xamaipak | K6: Tuxtla Gutierrez | L6: 29060
A7: Chihuahua-Almacen Estatal Chihuahua | B7: 2345 | C7: No aplica | D7: 008-146-00 | E7: 008_146_00_Almacen_Estatal_Chihuahua | F7: AE | G7: Unidad Administrativa | H7: Chihuahua | I7: Almacen Estatal Chihuahua | J7: Av. Octavio Paz No. 101 Col. Complejo Industrial | K7: Chihuahua | L7: 31109
A8: Coahuila-Almacen Estatal Coahuila | B8: 2082 | C8: No aplica | D8: 005-142-00 | E8: 005_142_00_Almacen_Estatal_Coahuila | F8: AE | G8: Unidad Administrativa | H8: Coahuila | I8: Almacen Estatal Coahuila | J8: Andres Saucedo 1368 Col. Deportivo | K8: Saltillo | L8: 25284
A9: Colima-Almacen Estatal Colima | B9: 2599 | C9: No aplica | D9: 006-142-00 | E9: 006_142_00_Almacen_Estatal_Colima | F9: AE | G9: Unidad Administrativa | H9: Colima | I9: Almacen Estatal Colima | J9: Manuel Acuna 595 PB Col. Jardines Residenciales | K9: Colima | L9: 28010
A10: Durango-Almacen Estatal Durango | B10: 2156 | C10: No aplica | D10: 010-142-00 | E10: 010_142_00_Almacen_Estatal_Durango | F10: AE | G10: Unidad Administrativa | H10: Durango | I10: Almacen Estatal Durango | J10: Av. Estroncio No. 100, Col. Agricola 20 de Noviembre | K10: Durango | L10: 34227
A11: Guanajuato-Almacen Estatal Guanajuato | B11: 2043 | C11: No aplica | D11: 011-142-00 | E11: 011_142_00_Almacen_Estatal_Guanajuato | F11: AE | G11: Unidad Administrativa | H11: Guanajuato | I11: Almacen Estatal Guanajuato | J11: Salvador Ortega No. 503 Col. Las Aves | K11: Celaya | L11: 38080
A12: Guerrero-Almacen Estatal Guerrero | B12: 2651 | C12: No aplica | D12: 012-142-00 | E12: 012_142_00_Almacen_Estatal_Guerrero | F12: AE | G12: Unidad Administrativa | H12: Guerrero | I12: Almacen Estatal Guerrero | J12: Vasco Nunez de Balboa No. 12 Col. Centro | K12: Acapulco | L12: 39300
A13: Yucatan-Almacen Estatal Merida | B13: 3903 | C13: No aplica | D13: 031-145-00 | E13: 031_145_00_Almacen_Estatal_Merida | F13: AE | G13: Unidad Administrativa | H13: Yucatan | I13: Almacen Estatal Merida | J13: 17 Lote 412 Por 20 y 24 Av. Cabalan Macari Col. Ciudad Industrial | K13: Merida | L13: 97288
... A27: CDMX-APP Tlahuac | B27: 4547 | C27: DFIST001053 | D27: 093-220-00 | E27: 093_220_00_APP_Tlahuac | F27: APP | G27: Unidad Medica | H27: CDMX | I27: APP Tlahuac | J27: Avenida Heberto Castillo No. 216, Col. Villa Centroamericana | K27: Tlahuac | L27: 13278
A28: CDMX-Area Auditoria para el Desarrollo y Mejora | C28: No aplica | E28: _Area_Auditoria_para_el_Desarrollo_y_Mejora | G28: Unidad Administrativa | H28: CDMX | I28: Area Auditoria para el Desarrollo y Mejora
A29: CDMX-Area de Auditoria Interma y Area Quejas en Delegacion | C29: No aplica | E29: _Area_de_Auditoria_Interma_y_Area_Quejas_en_Delegacion | G29: Unidad Administrativa | H29: CDMX | I29: Area de Auditoria Interma y Area Quejas en Delegacion
A30: Chihuahua-BP No 10 Chihuahua | B30: 2342 | C30: No aplica | D30: 008-304-81 | E30: 008_304_81_BP_No_10_Chihuahua | F30: BP | G30: Unidad Administrativa | H30: Chihuahua | I30: BP No 10 Chihuahua | J30: Oceano Pacifico No. 3620 Col. Fovissste | K30: Chihuahua | L30: 31290
A31: CDMX-BP No 12 Flores Magon y Lazaro Cardenas | B31: 2377 | C31: No aplica | D31: 091-304-83 | E31: 091_304_83_BP_No_12_Flores_Magon_y_Lazaro_Cardenas | F31: BP | G31: Unidad Administrativa | H31: CDMX | I31: BP No 12 Flores Magon y Lazaro Cardenas | J31: Lazaro Cardenas 402 Edif.11 Col. Tlatelolco | K31: Cuauhtemoc | L31: 06300
A32: Coahuila-BP No 19 Torreon | B32: 2081 | C32: No aplica | D32: 005-304-82 | E32: 005_304_82_BP_No_19_Torreon | F32: BP | G32: Unidad Administrativa | H32: Coahuila | I32: BP No 19 Torreon | J32: Francisco I. No 110 Madero Esq. Abasolo Col. Centro | K32: Torreon | L32: 27140
A33: Estado de Mexico-BP No 21 Texcoco | B33: 2448 | C33: No aplica | D33: 015-304-95 | E33: 015_304_95_BP_No_21_Texcoco | F33: BP | G33: Unidad Administrativa | H33: Estado de Mexico | I33: BP No 21 Texcoco | J33: Av. 16 de Septiembre No. 107 Col. Centro | K33: Texcoco | L33: 56100
A34: Estado de Mexico-BP No 35 Ecatepec | B34: 2437 | C34: No aplica | D34: 015-304-86 | E34: 015_304_86_BP_No_35_Ecatepec | F34: BP | G34: Unidad Administrativa | H34: Estado de Mexico | I34: BP No 35 Ecatepec | J34: Guelatao No. 133 Col. Santa Maria Tultetlac | K34: Ecatepec de Morelos | L34: 55400
A35: Guanajuato-BP No 48 Celaya | B35: 2186 | C35: No aplica | D35: 011-304-82 | E35: 011_304_82_BP_No_48_Celaya | F35: BP | G35: Unidad Administrativa | H35: Guanajuato | I35: BP No 48 Celaya | J35: Av. Francisco Juarez Esq. Las Americas Col. Los Laureles | K35: Celaya | L35: 38020
A36: San Luis Potosi-BP No 50 Cd Valles | B36: 2732 | C36: No aplica | D36: 024-304-83 | E36: 024_304_83_BP_No_50_Cd_Valles | F36: BP | G36: Unidad Administrativa | H36: San Luis Potosi | I36: BP No 50 Cd Valles | J36: Pedro Antonio de los Santos SN Col. Centro | K36: Cd Valles | L36: 79040
A37: Puebla-BP No 53 Puebla | B37: 2244 | C37: No aplica | D37: 021-304-80 | E37: 021_304_80_BP_No_53_Puebla | F37: BP | G37: Unidad Administrativa | H37: Puebla | I37: BP No 53 Puebla | J37: Privada Yucatan No. 1444 Col. Universidades | K37: Puebla | L37: 72590
A38: CDMX-BP No 6 Felix Cuevas | B38: 2151 | C38: No aplica | D38: 093-304-80 | E38: 093_304_80_BP_No_6_Felix_Cuevas | F38: BP | G38: Unidad Administrativa | H38: CDMX | I38: BP No 6 Felix Cuevas | J38: Edif. C. C.U.P.A.. Av. Coyoacan 1435. Esq. Felix Cuevas. Piso PB Col. Valle Sur | K38: Benito Juarez | L38: 03100
A39: CDMX-BP No 7 UH Tlatelolco | B39: 2103 | C39: No aplica | D39: 091-304-80 | E39: 091_304_80_BP_No_7_UH_Tlatelolco | F39: BP | G39: Unidad Administrativa | H39: CDMX | I39: BP No 7 UH Tlatelolco | J39: Manuel Gonzalez Esq. Insurgentes SN Col. Tlatelolco | K39: Gustavo A. Madero | L39: 06900
A40: Yucatan-BP No 9 Merida | B40: 2530 | C40: No aplica | D40: 031-304-80 | E40: 031_304_80_BP_No_9_Merida | F40: BP | G40: Unidad Administrativa | H40: Yucatan | I40: BP No 9 Merida | J40: 5 por Av. 36 Col. Pensiones | K40: Merida | L40: 97219
A41: Morelos-C Aux Issstehuixtla | B41: 2688 | C41: No aplica | D41: 017-206-17 | E41: 017_206_17_C_Aux_Issstehuixtla | G41: Unidad Administrativa | H41: Morelos | I41: C Aux Issstehuixtla | J41: Av. de la Fundicion SN Col. Issstehuixtla | K41: Guadalupe | L41: 62910
A42: Tamaulipas-C Cult Ciudad Victoria | B42: 2762 | C42: No aplica | D42: 028-304-82 | E42: 028_304_82_C_Cult_Ciudad_Victoria | F42: C_Cult | G42: Unidad Administrativa | H42: Tamaulipas | I42: C Cult Ciudad Victoria | J42: Luis H. Mora No. 544 Col. Fracc. Las Flores | K42: Cd Victoria | L42: 87078
A43: Yucatan-C Cult Merida | B43: 2527 | C43: No aplica | D43: 031-304-81 | E43: 031_304_81_C_Cult_Merida | F43: C_Cult | G43: Unidad Administrativa | H43: Yucatan | I43: C Cult Merida | J43: 5 A SN Por 38A y 40 Col. Fracc. Fovissste Pensiones | K43: Merida | L43: 97217
A44: CDMX-CA Unidad de Comunicacion Social | C44: No aplica | D44: 107-144-00 | E44: 107_144_00_CA_Unidad_de_Comunicacion_Social | G44: Unidad Administrativa | H44: CDMX | I44: CA Unidad de Comunicacion Social | J44: Jesus Garcia Corona No. 140 Col. Buenavista | K44: Cuauhtemoc | L44: 06350
A45: Puebla-CAF Acatzingo de Hidalgo | B45: 4604 | C45: PLIST000224 | D45: 021-214-11 | E45: 021_214_11_CAF_Acatzingo_de_Hidalgo | F45: CAF | G45: Unidad Medica | H45: Puebla | I45: CAF Acatzingo de Hidalgo | J45: 2 Poniente 305 Col. Barrio San Antonio | K45: Acatzingo de Hidalgo | L45: 75150
A46: Nuevo Leon-CAF Aramberri | B46: 3193 | C46: NLIST000233 | D46: 019-204-01 | E46: 019_204_01_CAF_Aramberri | F46: CAF | G46: Unidad Medica | H46: Nuevo Leon | I46: CAF Aramberri | J46: Felix Ccontreras SN entre Zaragoza y Naranjo Col. Centro | K46: Aramberri | L46: 67940
A47: Morelos-CAF Atlatlahucan | B47: 2591 | C47: MSIST000310 | D47: 017-205-11 | E47: 017_205_11_CAF_Atlatlahucan | F47: CAF | G47: Unidad Medica | H47: Morelos | I47: CAF Atlatlahucan | J47: Hermenegildo Galeana Esq. Ecuador SN Col. Barrio San Sebastian | K47: Atlatlahucan | L47: 62840
A48: Morelos-CAF Axochiapan | B48: 3898 | C48: MSIST000136 | D48: 017-205-09 | E48: 017_205_09_CAF_Axochiapan | F48: CAF | G48: Unidad Medica | H48: Morelos | I48: CAF Axochiapan | J48: Galeana No. 21 Col. Centro | K48: Axochiapan | L48: 62950
A49: Quintana Roo-CAF Bakalar | B49: 4583 | C49: QRIST000096 | D49: 023-204-03 | E49: 023_204_03_CAF_Bakalar | F49: CAF | G49: Unidad Medica | H49: Quintana Roo | I49: CAF Bakalar | J49: 19 B Reg 5 Mzna. 8 Lt. 10 entre 42 y 44 Col. Colosio | K49: Bakalar | L49: 77930
A50: Morelos-CAF Cd Ayala | B50: 4554 | C50: MSIST000141 | D50: 017-205-04 | E50: 017_205_04_CAF_Cd_Ayala | F50: CAF | G50: Unidad Medica | H50: Morelos | I50: CAF Cd Ayala | J50: Pablo Torres Burgos No. 35 entre Vicente Guerrero y Miguel Hidalgo Col. Centro | K50: Cd. Ayala | L50: 62700
A51: Zacatecas-CAF Cd Cuauhtemoc | B51: Pendiente | C51: ZSIST000266 | D51: 032-204-33 | E51: 032_204_33_CAF_Cd_Cuauhtemoc | F51: CAF | G51: Unidad Medica | H51: Zacatecas | I51: CAF Cd Cuauhtemoc | J51: C. San Juan de Dios No.5 Col. La Gavia San Pedro Piedra Gorda | K51: Cuauhtemoc | L51: 98613
A52: Tamaulipas-CAF Cd Mier | B52: 3360 | C52: TSIST000281 | D52: 028-206-05 | E52: 028_206_05_CAF_Cd_Mier | F52: CAF | G52: Unidad Medica | H52: Tamaulipas | I52: CAF Cd Mier | J52: Guerrero y Obregon SN Col. Centro | K52: Cd Mier | L52: 88390
A53: Guerrero-CAF Cd Renacimiento | B53: 2665 | C53: GRIST000322 | D53: 012-208-03 | E53: 012_208_03_CAF_Cd_Renacimiento | F53: CAF | G53: Unidad Medica | H53: Guerrero | I53: CAF Cd Renacimiento | J53: 13 SN entre Calles 14 y 3 Frente A Canchas de Futbol Col. Emiliano Zapata | K53: Acapulco | L53: 39700
...

Sheet Aux
A1: ENTIDAD_FEDERATIVA | B1: CARGO_AUTORIZO | C1: CARGO_EMPLEADO | D1: AREA_ADSCRIPCION | E1: OFICINA | F1: CENTRO_TRABAJO
A2: Aguascalientes | B2: Director | C2: Administrador de Velatorio A | D2: CMN 20 de Noviembre | E2: Abarrotes | F2: Almacen Estatal Aguascalientes
A3: Baja California | B3: Directora | C3: Administrador de Velatorio B | D3: Direccion de Administracion y Finanzas | E3: Abastecimiento y Servicios Generales | F3: Almacen Estatal Baja California
A4: Baja California Sur | B4: Subdirector | C4: Administrativo Especializado | D4: Direccion de Incorporacion Recaudacion e Inversiones | E4: Activo Fijo | F4: Almacen Estatal Baja California Sur
A5: Campeche | B5: Subdirectora | C5: Administrativo General | D5: Direccion de Oficinas de Representacion | E5: Activo Fijo e Inventarios | F5: Almacen Estatal Campeche
A6: CDMX | B6: Coordinador | C6: Analista Administrativo | D6: Direccion de Prestaciones Economicas Sociales y Culturales | E6: Administracion | F6: Almacen Estatal Chiapas
A7: Chiapas | B7: Coordinadora | C7: Analista Control de Expedientes | D7: Direccion Estrategica de Informacion Supervision y Evaluacion | E7: Administracion Agencia TURISSSTE | F7: Almacen Estatal Chihuahua
A8: Chihuahua | B8: Subcoordinador | C8: Analista de Control A | D8: Direccion General | E8: Administracion ISSSTEHUIXTLA | F8: Almacen Estatal Coahuila
A9: Coahuila | B9: Subcoordinadora | C9: Analista de Control B | D9: Direccion Juridica | E9: Administracion Velatorio Cementerio y Panteon | F9: Almacen Estatal Colima
A10: Colima | B10: Tesorero | C10: Analista de Control C | D10: Direccion Medica | E10: Admision Continua Adultos | F10: Almacen Estatal Durango
A11: Durango | B11: Tesorera | C11: Analista de Proyectos | D11: Escuela de Dietetica y Nutricion | E11: Admision Continua Pediatrica | F11: Almacen Estatal Guanajuato
A12: Estado de Mexico | B12: Subdelegado | C12: Analista Ejecutivo en Proyectos | D12: Fondo Nacional de Pensiones de los Trabajadores al Servicio del Estado | E12: Admision Hospitalaria | F12: Almacen Estatal Guerrero
... A18: Morelos | B18: Jefa de Unidad | C18: Apoyo Administrativo en Salud A4 | D18: HAE Leon | E18: Almacen General | F18: Almacen Estatal Quintana Roo
A19: Nayarit | C19: Apoyo Administrativo en Salud A5 | D19: HAE Lic Adolfo Lopez Mateos | E19: Almacen y Viveres | F19: Almacen Estatal San Luis Potosi
A20: Nuevo Leon | C20: Apoyo Administrativo en Salud A6 | D20: HAE Merida Elvia Carrillo Puerto | E20: Anatomia Patologica | F20: Almacen Estatal Sonora
A21: Oaxaca | C21: Apoyo Administrativo en Salud A7 | D21: HAE Monterrey | E21: Anestesiologia | F21: Almacen Estatal Tabasco
A22: Puebla | C22: Apoyo Administrativo en Salud A8 | D22: HAE Morelia | E22: Angiologia | F22: Almacen Estatal Tamaulipas
A23: Queretaro | C23: Asistente Administrativo A | D23: HAE Primero de Octubre | E23: Angiologia y Cirugia Vascular | F23: Almacen Estatal Tlaxcala
A24: Quintana Roo | C24: Asistente Administrativo B | D24: HAE Presidente Benito Juarez Oax | E24: Area de Analisis de Procesos Informaticos | F24: Almacen Estatal Zacatecas
A25: San Luis Potosi | C25: Asistente Administrativo C | D25: HAE Puebla Pue | E25: Apoyo Artesanos | F25: APP Merida
A26: Sinaloa | C26: Asistente Administrativo D | D26: HAE Tlajomulco de Zuniga | E26: Apoyo y Medios Educativos | F26: APP Tepic
A27: Sonora | C27: Asistente Administrativo en Salud A1 | D27: HAE Torreon | E27: Archivo Clinico | F27: APP Tlahuac
A28: Tabasco | C28: Asistente Administrativo en Salud A2 | D28: HAE Veracruz Ver | E28: Archivo y Correspondencia | F28: Area Auditoria para el Desarrollo y Mejora
A29: Tamaulipas | C29: Asistente Administrativo en Salud A3 | D29: Organo Interno de Control en el ISSSTE | E29: Area Auditoria para el Desarrollo y Mejora de la Gestion | F29: Area de Auditoria Interma y Area Quejas en Delegacion
A30: Tlaxcala | C30: Asistente Administrativo en Salud A4 | D30: Organo Interno de Control en el SUPERISSSTE | E30: Area de Administracion de Base de Datos | F30: BP No 10 Chihuahua
... A33: Zacatecas | C33: Asistente Administrativo en Salud A7 | D33: Representacion Estatal Baja California Sur | E33: Area de Analisis | F33: BP No 21 Texcoco
C34: Asistente Administrativo en Salud A8 | D34: Representacion Estatal Campeche | E34: Area de Analisis de Inversiones | F34: BP No 35 Ecatepec
C35: Asistente A de la Direccion de Hospital | D35: Representacion Estatal Chiapas | E35: Area de Analisis de Mercado | F35: BP No 48 Celaya
C36: Asistente de Cocina en Unidad Hospitalaria | D36: Representacion Estatal Chihuahua | E36: Area de Analisis de Procesos de Traspasos de Afore | F36: BP No 50 Cd Valles
C37: Asistente de la Direccion de Hospital | D37: Representacion Estatal Coahuila | E37: Area de Analisis de Procesos Financieros de Afore | F37: BP No 53 Puebla
C38: Auxiliar Administrador | D38: Representacion Estatal Colima | E38: Area de Analisis de Registros de Afore | F38: BP No 6 Felix Cuevas
C39: Auxiliar Administrativo | D39: Representacion Estatal Durango | E39: Area de Analisis Fiscal | F39: BP No 7 UH Tlatelolco
C40: Auxiliar Contabilidad | D40: Representacion Estatal Estado de Mexico | E40: Area de Analisis Operativa Administrativa y Financiera | F40: BP No 9 Merida
C41: Auxiliar Contable | D41: Representacion Estatal Guanajuato | E41: Area de Analisis y Liquidacion de Operaciones | F41: C Aux Issstehuixtla
C42: Auxiliar de Admision | D42: Representacion Estatal Guerrero | E42: Area de Apoyo | F42: C Cult Ciudad Victoria
C43: Auxiliar de Almacen | D43: Representacion Estatal Hidalgo | E43: Area de Archivo y Control Documental | F43: C Cult Merida
C44: Auxiliar de Caja | D44: Representacion Estatal Jalisco | E44: Area de Asuntos Legales de Organos de Gobierno y Colegiados | F44: CA Unidad de Comunicacion Social
C45: Auxiliar de Cajero | D45: Representacion Estatal Michoacan | E45: Area de Asuntos Legales de Sociedades de Inversion | F45: CAF Acatzingo de Hidalgo
... C69: Chofer de Subdirector de Area | D69: Unidad de Comunicacion Social | E69: Area de Quejas | F69: CAF Hidalgo
C70: Cirujano Dentista A | E70: Area de Recaudacion | F70: CAF Higuera de Zaragoza
...

Sheet Comentarios
A1: llave | B1: Tipo de solicitud | C1: Servicios | D1: TIPO DE SOLICITUD O SERVICIO | E1: DESCRIPCIÓN Y JUSTIFICACIÓN
A2: ALTA - ABC - AD USUARIO | B2: ALTA | C2: ABC | D2: Si el tipo de solicitud es una alta de usuario de nuevo ingreso, previamente debe levantar el ticket de la baja del servidor publico que deja el cargo e indicar el usuario y No. de ticket. | E2: En caso de solicitar un alta de usuario para personal operativo, favor de indicar el detalle de las funciones del usuario que lo justifique. | F2: USUARIO | G2: ENLACE INFORMATICO | H2: JEFE DE SERVICIOS O SUPERIOR | I2: El presente documento es una responsiva mediante la cual el usuario acepta las Políticas de uso del servicio solicitado, publicadas en la Intranet del Instituto en el siguiente link: https://www.issste.gob.mx/intranet/direccionnormativa/adminitracionyfinanzas/sudireccion/masinfo/acuerdotic.html
A3: ALTA - ABC - AD-EX USUARIO Y CUENTA DE CORREO | B3: ALTA | C3: ABC | D3: Si el tipo de solicitud es una alta de usuario y/o cuenta de correo electrónico de nuevo ingreso, previamente debe levantar el ticket de la baja del servidor publico que deja el cargo e indicar el usuario y No. de ticket. | E3: En caso de solicitar un alta de usuario y/o de cuenta de correo electrónico para personal operativo, favor de indicar el detalle de las funciones del usuario que lo justifique. | F3: USUARIO | G3: ENLACE INFORMATICO | H3: JEFE DE SERVICIOS O SUPERIOR | I3: El presente documento es una responsiva mediante la cual el usuario acepta las Políticas de uso del servicio solicitado, publicadas en la Intranet del Instituto en el siguiente link: https://www.issste.gob.mx/intranet/direccionnormativa/adminitracionyfinanzas/sudireccion/masinfo/acuerdotic.html
A4: ALTA - ABC - EX CUENTA DE CORREO | B4: ALTA | C4: ABC | D4: Si el tipo de solicitud es una alta de cuenta de correo electrónico, previamente debe levantar el ticket de la baja del servidor publico que deja el cargo e indicar el usuario y No. de ticket. | E4: En caso de solicitar un alta de cuenta de correo electrónico para personal operativo, favor de indicar el detalle de las funciones del usuario que lo justifique. | F4: USUARIO | G4: ENLACE INFORMATICO | H4: JEFE DE SERVICIOS O SUPERIOR | I4: El presente documento es una responsiva mediante la cual el usuario acepta las Políticas de uso del servicio solicitado, publicadas en la Intranet del Instituto en el siguiente link: https://www.issste.gob.mx/intranet/direccionnormativa/adminitracionyfinanzas/sudireccion/masinfo/acuerdotic.html
A5: ALTA - PERFILES_DE_ACCESO_A_INTERNET - ADMINISTRATIVO BASICO | B5: ALTA | C5: PERFILES_DE_ACCESO_A_INTERNET | D5: Si el tipo de solicitud es una alta de perfil de acceso a internet, favor de indicar el usuario de dominio al que se le asignará dicho perfil. | E5: En caso de solicitar un alta de perfil de acceso a internet, favor de indicar el detalle de las funciones del usuario que lo justifique. | F5: USUARIO | G5: ENLACE INFORMATICO | H5: JEFE DE SERVICIOS O SUPERIOR | I5: El presente documento es una responsiva mediante la cual el usuario acepta las Políticas de uso del servicio solicitado, publicadas en la Intranet del Instituto en el siguiente link: https://www.issste.gob.mx/intranet/direccionnormativa/adminitracionyfinanzas/sudireccion/masinfo/acuerdotic.html
A6: ALTA - PERFILES_DE_ACCESO_A_INTERNET - ADMINISTRATIVO ELEVADO | B6: ALTA | C6: PERFILES_DE_ACCESO_A_INTERNET | D6: Si el tipo de solicitud es una alta de perfil de acceso a internet, favor de indicar el usuario de dominio al que se le asignará dicho perfil. | E6: En caso de solicitar un alta de perfil de acceso a internet, favor de indicar el detalle de las funciones del usuario que lo justifique. | F6: USUARIO | G6: ENLACE INFORMATICO | H6: JEFE DE SERVICIOS O SUPERIOR | I6: El presente documento es una responsiva mediante la cual el usuario acepta las Políticas de uso del servicio solicitado, publicadas en la Intranet del Instituto en el siguiente link: https://www.issste.gob.mx/intranet/direccionnormativa/adminitracionyfinanzas/sudireccion/masinfo/acuerdotic.html
A7: ALTA - PERFILES_DE_ACCESO_A_INTERNET - BASICO | B7: ALTA | C7: PERFILES_DE_ACCESO_A_INTERNET | D7: Si el tipo de solicitud es una alta de perfil de acceso a internet, favor de indicar el usuario de dominio al que se le asignará dicho perfil. | E7: En caso de solicitar un alta de perfil de acceso a internet, favor de indicar el detalle de las funciones del usuario que lo justifique. | F7: USUARIO | G7: ENLACE INFORMATICO | H7: JEFE DE SERVICIOS O SUPERIOR | I7: El presente documento es una responsiva mediante la cual el usuario acepta las Políticas de uso del servicio solicitado, publicadas en la Intranet del Instituto en el siguiente link: https://www.issste.gob.mx/intranet/direccionnormativa/adminitracionyfinanzas/sudireccion/masinfo/acuerdotic.html
A8: ALTA - PERFILES_DE_ACCESO_A_INTERNET - COMUNICACIÓN SOCIAL | B8: ALTA | C8: PERFILES_DE_ACCESO_A_INTERNET | D8: Si el tipo de solicitud es una alta de perfil de acceso a internet, favor de indicar el usuario de dominio al que se le asignará dicho perfil. | E8: En caso de solicitar un alta de perfil de acceso a internet, favor de indicar el detalle de las funciones del usuario que lo justifique. | F8: USUARIO | G8: ENLACE INFORMATICO | H8: JEFE DE SERVICIOS O SUPERIOR | I8: El presente documento es una responsiva mediante la cual el usuario acepta las Políticas de uso del servicio solicitado, publicadas en la Intranet del Instituto en el siguiente link: https://www.issste.gob.mx/intranet/direccionnormativa/adminitracionyfinanzas/sudireccion/masinfo/acuerdotic.html
A9: ALTA - PERFILES_DE_ACCESO_A_INTERNET - DIRECTIVO | B9: ALTA | C9: PERFILES_DE_ACCESO_A_INTERNET | D9: Si el tipo de solicitud es una alta de perfil de acceso a internet, favor de indicar el usuario de dominio al que se le asignará dicho perfil. | E9: En caso de solicitar un alta de perfil de acceso a internet, favor de indicar el detalle de las funciones del usuario que lo justifique. | F9: USUARIO | G9: ENLACE INFORMATICO | H9: JEFE DE SERVICIOS O SUPERIOR | I9: El presente documento es una responsiva mediante la cual el usuario acepta las Políticas de uso del servicio solicitado, publicadas en la Intranet del Instituto en el siguiente link: https://www.issste.gob.mx/intranet/direccionnormativa/adminitracionyfinanzas/sudireccion/masinfo/acuerdotic.html
A10: ALTA - PERFILES_DE_ACCESO_A_INTERNET - ENSEÑANZA | B10: ALTA | C10: PERFILES_DE_ACCESO_A_INTERNET | D10: Si el tipo de solicitud es una alta de perfil de acceso a internet, favor de indicar el usuario de dominio al que se le asignará dicho perfil. | E10: En caso de solicitar un alta de perfil de acceso a internet, favor de indicar el detalle de las funciones del usuario que lo justifique. | F10: USUARIO | G10: ENLACE INFORMATICO | H10: JEFE DE SERVICIOS O SUPERIOR | I10: El presente documento es una responsiva mediante la cual el usuario acepta las Políticas de uso del servicio solicitado, publicadas en la Intranet del Instituto en el siguiente link: https://www.issste.gob.mx/intranet/direccionnormativa/adminitracionyfinanzas/sudireccion/masinfo/acuerdotic.html
A11: ALTA - PERFILES_DE_ACCESO_A_INTERNET - MEDICO BASICO | B11: ALTA | C11: PERFILES_DE_ACCESO_A_INTERNET | D11: Si el tipo de solicitud es una alta de perfil de acceso a internet, favor de indicar el usuario de dominio al que se le asignará dicho perfil. | E11: En caso de solicitar un alta de perfil de acceso a internet, favor de indicar el detalle de las funciones del usuario que lo justifique. | F11: USUARIO | G11: ENLACE INFORMATICO | H11: JEFE DE SERVICIOS O SUPERIOR | I11: El presente documento es una responsiva mediante la cual el usuario acepta las Políticas de uso del servicio solicitado, publicadas en la Intranet del Instituto en el siguiente link: https://www.issste.gob.mx/intranet/direccionnormativa/adminitracionyfinanzas/sudireccion/masinfo/acuerdotic.html
A12: ALTA - PERFILES_DE_ACCESO_A_INTERNET - MEDICO ELEVADO | B12: ALTA | C12: PERFILES_DE_ACCESO_A_INTERNET | D12: Si el tipo de solicitud es una alta de perfil de acceso a internet, favor de indicar el usuario de dominio al que se le asignará dicho perfil. | E12: En caso de solicitar un alta de perfil de acceso a internet, favor de indicar el detalle de las funciones del usuario que lo justifique. | F12: USUARIO | G12: ENLACE INFORMATICO | H12: JEFE DE SERVICIOS O SUPERIOR | I12: El presente documento es una responsiva mediante la cual el usuario acepta las Políticas de uso del servicio solicitado, publicadas en la Intranet del Instituto en el siguiente link: https://www.issste.gob.mx/intranet/direccionnormativa/adminitracionyfinanzas/sudireccion/masinfo/acuerdotic.html
A13: BAJA - ABC - AD USUARIO | B13: BAJA | C13: ABC | D13: Indique el usuario de dominio que se dará de baja. | E13: Indique el motivo de la baja del usuario de dominio. | F13: USUARIO | G13: ENLACE INFORMATICO | H13: JEFE DE SERVICIOS O SUPERIOR | I13: El presente documento es una responsiva mediante la cual el usuario acepta las Políticas de uso del servicio solicitado, publicadas en la Intranet del Instituto en el siguiente link: https://www.issste.gob.mx/intranet/direccionnormativa/adminitracionyfinanzas/sudireccion/masinfo/acuerdotic.html
... A35: ALTA - LICENCIA - Licencia Office 365 | B35: ALTA | C35: Licencia Office 365 | D35: Si el tipo de solicitud es de Licencia para Office 365 ,favor de adjuntar en formato PDF la evidencia donde se visualice el usuario y la version de Office, el hostname y dirección IP. | E35: Si el tipo de solicitud es de Licencia para Office 365, favor de indicar el detalle de las funciones del usuario que lo justifique. | F35: USUARIO | G35: ENLACE INFORMATICO | H35: JEFE DE SERVICIOS O SUPERIOR | I35: Le solicitamos que cumpla con los principios y directrices establecidos en el artículo 7, fracciones I y VI de la Ley General de Responsabilidades Administrativas que a la letra dice: “Artículo 7. Las personas Servidoras Publicas observarán en el desempeño de su empleo, cargo o comisión, los principios de austeridad, disciplina, legalidad, objetividad, profesionalismo, honradez, lealtad, imparcialidad, integridad, rendición de cuentas, eficacia y eficiencia y racionalidad en el uso de los recursos públicos, mismos que rigen el servicio público.

Sheet Catalogo
A1: Servicio | B1: Servicio_tipo | C1: Servicios
A2: ACB | B2: AD USUARIO | C2: ABC
A3: ABC | B3: AD-EX USUARIO Y CUENTA DE CORREO | C3: PERFILES_DE_ACCESO_A_INTERNET
A4: ABC | B4: EX CUENTA DE CORREO | C4: LICENCIA
A5: Perfiles de acceso a internet | B5: DIRECTIVO
A6: Perfiles de acceso a internet | B6: ADMINISTRATIVO ELEVADO
A7: Perfiles de acceso a internet | B7: MEDICO ELEVADO
A8: Perfiles de acceso a internet | B8: ADMINISTRATIVO BASICO
A9: Perfiles de acceso a internet | B9: MEDICO BASICO
A10: Perfiles de acceso a internet | B10: BASICO
A11: Perfiles de acceso a internet | B11: COMUNICACIÓN SOCIAL
A12: Perfiles de acceso a internet | B12: ENSEÑANZA
A13: LICENCIA | B13: Licencia Office 365
